2021-11-14 11:00:49,906 INFO    MainThread:3460341 [wandb_setup.py:_flush():71] setting env: {}
2021-11-14 11:00:49,906 INFO    MainThread:3460341 [wandb_setup.py:_flush():71] setting login settings: {}
2021-11-14 11:00:49,906 INFO    MainThread:3460341 [wandb_init.py:_log_setup():357] Logging user logs to /home/masumoto/coper/CoPER_ConvE/wandb/run-20211114_110049-3u6ltgk9/logs/debug.log
2021-11-14 11:00:49,906 INFO    MainThread:3460341 [wandb_init.py:_log_setup():358] Logging internal logs to /home/masumoto/coper/CoPER_ConvE/wandb/run-20211114_110049-3u6ltgk9/logs/debug-internal.log
2021-11-14 11:00:49,907 INFO    MainThread:3460341 [wandb_init.py:init():390] calling init triggers
2021-11-14 11:00:49,907 INFO    MainThread:3460341 [wandb_init.py:init():397] wandb.init called with sweep_config: {}
config: {}
2021-11-14 11:00:49,907 INFO    MainThread:3460341 [wandb_init.py:init():435] starting backend
2021-11-14 11:00:49,907 INFO    MainThread:3460341 [backend.py:_multiprocessing_setup():97] multiprocessing start_methods=fork,spawn,forkserver, using: spawn
2021-11-14 11:00:49,918 INFO    MainThread:3460341 [backend.py:ensure_launched():199] starting backend process...
2021-11-14 11:00:49,967 ERROR   MainThread:3460341 [wandb_init.py:init():897] error
Traceback (most recent call last):
  File "/home/masumoto/anaconda3/envs/py36_tf114/lib/python3.6/site-packages/wandb/sdk/wandb_init.py", line 870, in init
    run = wi.init()
  File "/home/masumoto/anaconda3/envs/py36_tf114/lib/python3.6/site-packages/wandb/sdk/wandb_init.py", line 442, in init
    backend.ensure_launched()
  File "/home/masumoto/anaconda3/envs/py36_tf114/lib/python3.6/site-packages/wandb/sdk/backend/backend.py", line 202, in ensure_launched
    self.wandb_process.start()
  File "/home/masumoto/anaconda3/envs/py36_tf114/lib/python3.6/multiprocessing/process.py", line 105, in start
    self._popen = self._Popen(self)
  File "/home/masumoto/anaconda3/envs/py36_tf114/lib/python3.6/multiprocessing/context.py", line 284, in _Popen
    return Popen(process_obj)
  File "/home/masumoto/anaconda3/envs/py36_tf114/lib/python3.6/multiprocessing/popen_spawn_posix.py", line 32, in __init__
    super().__init__(process_obj)
  File "/home/masumoto/anaconda3/envs/py36_tf114/lib/python3.6/multiprocessing/popen_fork.py", line 19, in __init__
    self._launch(process_obj)
  File "/home/masumoto/anaconda3/envs/py36_tf114/lib/python3.6/multiprocessing/popen_spawn_posix.py", line 42, in _launch
    prep_data = spawn.get_preparation_data(process_obj._name)
  File "/home/masumoto/anaconda3/envs/py36_tf114/lib/python3.6/multiprocessing/spawn.py", line 143, in get_preparation_data
    _check_not_importing_main()
  File "/home/masumoto/anaconda3/envs/py36_tf114/lib/python3.6/multiprocessing/spawn.py", line 136, in _check_not_importing_main
    is not going to be frozen to produce an executable.''')
RuntimeError: 
        An attempt has been made to start a new process before the
        current process has finished its bootstrapping phase.

        This probably means that you are not using fork to start your
        child processes and you have forgotten to use the proper idiom
        in the main module:

            if __name__ == '__main__':
                freeze_support()
                ...

        The "freeze_support()" line can be omitted if the program
        is not going to be frozen to produce an executable.
